Workbook

Sheet Cover & Assumptions
A1: MERIDIAN TRUST BANK — M&A MERGER MODEL
A2: Project Northfield (Bank B) vs. Project Harborview (Bank C) | Board decision support
A3: Anchor year FY2025 (YE 31 Dec 2025) | CAD $ millions unless noted | Jurisdiction: Canada (fictional)
A5: FICTIONAL / SIMULATED DATA — All entities, financial figures, and events in this document are entirely fictional, created for illustrative/educational simulation purposes. They do not represent any real institution, and nothing here is financial, investment, or M&A advice.
A9: LEGEND & MODEL CONVENTIONS
A10: Blue text = hardcoded input / scenario lever taken from the case source spec
A11: Black text = formula computed on this sheet
A12: Green text = link to another worksheet in this workbook
A13: Yellow fill = headline output the board should read first
A14: All FY2025 anchor figures and all deal terms are taken verbatim from the case spec and are NOT re-derived.
A15: Forward-projection drivers (FY2026E-FY2028E) are model assumptions, disclosed in full below.
A16: Every derived figure in this workbook is a live formula — no hardcoded results.
A18: GLOBAL ASSUMPTIONS
A19: Item | B19: Value | D19: Source / note
A20: Tax rate | B20: 0.26 | D20: Case spec — applies to all synergy / EPS / return math
A21: Meridian internal CET1 target | B21: 0.11 | D21: Case spec s.5 — the trigger for sizing an equity raise
A22: Regulatory CET1 minimum incl. conservation buffer | B22: 0.07 | D22: 4.5% Pillar 1 + 2.5% CCB (fictional OSFI analog)
A23: Meridian share price ($/share) | B23: 44 | D23: 1.6x book on 3,300 equity / 120mm shares (case spec s.2)
A24: Meridian shares outstanding (mm) | B24: 120 | D24: Case spec s.2
A25: Short-term reinvestment / opportunity cost rate | B25: 0.03 | D25: MODEL ASSUMPTION — applied symmetrically to cash deployed and to new-equity proceeds held
A26: Terminal / exit P/E multiple (x) | B26: 12 | D26: MODEL ASSUMPTION — set below Meridian's own 12.8x; used only in the deal IRR
A27: Credit conversion factor on undrawn card lines | B27: 0.1 | D27: Basel III finalisation, unconditionally cancellable lines (spec s.0)
A28: Risk weight — revolver | B28: 0.75 | D28: Case spec s.0
A29: Risk weight — transactor | B29: 0.45 | D29: Case spec s.0
A30: Interchange rate on card purchase volume | B30: 0.015 | D30: Case spec s.0
A32: FORWARD-PROJECTION DRIVERS (FY2026E - FY2028E) — MODEL ASSUMPTIONS
A33: Driver (annual growth) | B33: Bank A | C33: Bank B | D33: Bank C | E33: Basis
A34: Interest income and interest expense | B34: 0.045 | C34: 0.1 | D34: 0.03 | E34: A: 4.5% asset CAGR (spec s.2). B: 24% historical receivable growth deliberately more than halved post-close as Meridian tightens underwriting. C: 2.5-3.0% asset CAGR (spec s.4).
A35: Non-interest income | B35: 0.045 | C35: 0.1 | D35: 0.03 | E35: Tracks the earning book
A36: Provision for credit losses | B36: 0.05 | C36: 0.15 | D36: 0.04 | E36: B is set deliberately ABOVE its receivable growth, per spec s.3: 'provision expense growing faster than receivables'
A37: Non-interest expense | B37: 0.035 | C37: 0.06 | D37: 0.03 | E37: A: positive operating leverage delivers the 5-6% net income growth in spec s.2
A38: Gross card receivables and undrawn lines | B38: 0.06 | C38: 0.1 | D38: 0.04 | E38: A and C per spec s.2 / s.4; B moderated post-close
A40: DEAL B — MERIDIAN ACQUIRES NORTHFIELD CARD BANK (all cash)
A41: Term | B41: Value | D41: Source / note
A42: Purchase price ($mm, all cash) | B42: 1650 | D42: Case spec s.5
A43: Northfield standalone implied value ($mm) | B43: 1320 | D43: 1.47x FY2025 book (spec s.3)
A44: Share funded with new senior debt | B44: 0.7 | D44: Case spec s.5
A45: New senior debt ($mm) | B45: ='Cover & Assumptions'!$B$42*'Cover & Assumptions'!$B$44 -> 1155
A46: Meridian cash / excess capital deployed ($mm) | B46: ='Cover & Assumptions'!$B$42-'Cover & Assumptions'!$B$45 -> 495
A47: Senior debt coupon | B47: 0.0525 | D47: Case spec s.5
...

Sheet Standalone Summary
A1: STANDALONE SUMMARY — FY2025 ANCHOR FINANCIALS AND FORWARD PROJECTIONS
A2: Bank A Meridian Trust | Bank B Northfield Card | Bank C Harborview Community
A3: Every FY2025 figure is a case-spec anchor entered verbatim (blue). Everything else is computed.
A5: FICTIONAL / SIMULATED DATA — All entities, financial figures, and events in this document are entirely fictional, created for illustrative/educational simulation purposes. They do not represent any real institution, and nothing here is financial, investment, or M&A advice.
A9: FY2025 BALANCE SHEET ($mm)
A10: Line item | B10: Bank A Meridian Trust | C10: Bank B Northfield Card | D10: Bank C Harborview Comm. | F10: Note
A11: Cash & equivalents | B11: 1800 | C11: 650 | D11: 520
A12: Investment securities | B12: 6200 | C12: 900 | D12: 1650
A13: Residential mortgages | B13: 19500 | C13: 0 | D13: 4900
A14: Commercial & business loans | B14: 8400 | C14: 0 | D14: 1450
A15: Credit card receivables (net) | B15: 1150 | C15: 7200 | D15: 340
A16: Other consumer loans | B16: 2950 | C16: 1150 | D16: 640
A17: Other assets | B17: 1000 | C17: 500 | D17: 300
A18: Total assets | B18: =SUM(B11:B17) -> 41000 | C18: =SUM(C11:C17) -> 10400 | D18: =SUM(D11:D17) -> 9800
A20: Total deposits | B20: 32500 | C20: 6100 | D20: 8200 | F20: A: 21,000 chequing/savings + 11,500 term/GIC. B: broker / direct-to-consumer. C: 6,300 chequing/savings + 1,900 term.
A21: Wholesale borrowings / securitization debt | B21: 4300 | C21: 2900 | D21: 550
A22: Other liabilities | B22: 900 | C22: 500 | D22: 250
A23: Total liabilities | B23: =SUM(B20:B22) -> 37700 | C23: =SUM(C20:C22) -> 9500 | D23: =SUM(D20:D22) -> 9000
A24: Common equity | B24: 3300 | C24: 900 | D24: 800
A25: Total liabilities & equity | B25: =B23+B24 -> 41000 | C25: =C23+C24 -> 10400 | D25: =D23+D24 -> 9800
A26: Check: total assets less total liabilities & equity | B26: =B18-B25 -> 0 | C26: =C18-C25 -> 0 | D26: =D18-D25 -> 0 | F26: Must be nil — confirms the spec's balance sheets tie out
A27: Memo: interest-bearing liabilities (deposits + wholesale) | B27: =B20+B21 -> 36800 | C27: =C20+C21 -> 9000 | D27: =D20+D21 -> 8750
A29: FY2025 INCOME STATEMENT ($mm)
A30: Line item | B30: Bank A | C30: Bank B | D30: Bank C | F30: Note
A31: Interest income | B31: 1780 | C31: 1540 | D31: 415
A32: Interest expense | B32: 820 | C32: 290 | D32: 165
A33: Net interest income | B33: =B31-B32 -> 960 | C33: =C31-C32 -> 1250 | D33: =D31-D32 -> 250
A34: Interchange & card fee income | B34: 64 | C34: 246 | D34: 21 | F34: B: 15,300 purchase volume x 1.5% interchange, plus fees
A35: Other fee income | B35: 410 | C35: 0 | D35: 38
A36: Non-interest income | B36: =B34+B35 -> 474 | C36: =C34+C35 -> 246 | D36: =D34+D35 -> 59
A37: Total revenue | B37: =B33+B36 -> 1434 | C37: =C33+C36 -> 1496 | D37: =D33+D36 -> 309
A38: Provision for credit losses | B38: 96 | C38: 385 | D38: 14
A39: Non-interest expense (opex) | B39: 780 | C39: 640 | D39: 195
A40: Pre-tax income | B40: =B37-B38-B39 -> 558 | C40: =C37-C38-C39 -> 471 | D40: =D37-D38-D39 -> 100
A41: Income tax | B41: =B40*'Cover & Assumptions'!$B$20 -> 145.08 | C41: =C40*'Cover & Assumptions'!$B$20 -> 122.46 | D41: =D40*'Cover & Assumptions'!$B$20 -> 26
A42: Net income | B42: =B40-B41 -> 412.92 | C42: =C40-C41 -> 348.54 | D42: =D40-D41 -> 74
A44: FY2025 CAPITAL & REGULATORY RATIOS
A45: Line item | B45: Bank A | C45: Bank B | D45: Bank C | F45: Note
A46: CET1 capital ($mm) | B46: 3050 | C46: 790 | D46: 760
A47: Risk-weighted assets ($mm) | B47: 22600 | C47: 6850 | D47: 4450
...

Sheet Deal B Pro Forma
A1: DEAL B PRO FORMA — PROJECT NORTHFIELD
A2: Meridian Trust Bank acquires Northfield Card Bank — all-cash acquisition
A3: Purchase accounting, pro forma balance sheet, capital walk and three-year accretion / dilution ($mm unless noted)
A5: FICTIONAL / SIMULATED DATA — All entities, financial figures, and events in this document are entirely fictional, created for illustrative/educational simulation purposes. They do not represent any real institution, and nothing here is financial, investment, or M&A advice.
A9: A. PURCHASE PRICE, VALUATION AND GOODWILL
A10: Item | B10: Amount | F10: Derivation / note
A11: Purchase price (all cash) | B11: ='Cover & Assumptions'!$B$42 -> 1650 | F11: Case spec s.5
A12: Target common equity at close (book) | B12: ='Standalone Summary'!$C$24 -> 900 | F12: Northfield Card Bank FY2025 book equity
A13: Less: Day-1 IFRS 9 provisioning gross-up | B13: =-'Cover & Assumptions'!$B$64 -> -115 | F13: Acquisition-accounting allowance build beyond the allowance already carried
A14: Net identifiable assets acquired | B14: =B12+B13 -> 785
A15: GOODWILL CREATED | B15: =B11-B14 -> 865 | F15: Purchase price less (target book equity less the Day-1 provision build)
A17: Implied price / book (x) | B17: =B11/B12 -> 1.8333333
A18: Implied price / FY2025 earnings (x) | B18: =B11/'Standalone Summary'!$C$42 -> 4.7340334
A19: Premium to standalone implied value | B19: =B11/'Cover & Assumptions'!$B$43-1 -> 0.25 | F19: Standalone value per case spec
A20: FY2025 earnings yield on purchase price | B20: ='Standalone Summary'!$C$42/B11 -> 0.21123636 | F20: Compare against the after-tax cost of the acquisition debt below — the gap is what drives accretion
A21: After-tax cost of acquisition debt | B21: ='Cover & Assumptions'!$B$47*(1-'Cover & Assumptions'!$B$20) -> 0.03885
A22: Spread of earnings yield over after-tax debt cost | B22: =B20-B21 -> 0.17238636
A24: B. SOURCES AND USES OF FUNDS
A25: Item | B25: Amount | C25: % of total | F25: Note
A26: Source: new senior debt | B26: ='Cover & Assumptions'!$B$45 -> 1155 | C26: =B26/B28 -> 0.7
A27: Source: Meridian cash / excess capital | B27: ='Cover & Assumptions'!$B$46 -> 495 | C27: =B27/B28 -> 0.3
A28: Total sources | B28: =B26+B27 -> 1650
A29: Use: cash consideration to target shareholders | B29: =B11 -> 1650
A30: Total uses | B30: =B29 -> 1650
A31: Memo: one-time integration cost, expensed in Year 1 (pretax) | B31: ='Cover & Assumptions'!$B$63 -> 180
A33: C. PRO FORMA COMBINED BALANCE SHEET AT CLOSE ($mm)
A34: Line item | B34: Bank A FY2025A | C34: Northfield Card Bank FY2025A | D34: Deal adjustments | E34: Pro forma combined | F34: Adjustment note
A35: Cash & equivalents | B35: ='Standalone Summary'!$B$11 -> 1800 | C35: ='Standalone Summary'!$C$11 -> 650 | D35: =-'Cover & Assumptions'!$B$46+B68 -> 559.5 | E35: =B35+C35+D35 -> 3009.5 | F35: Less the cash consideration funded from Meridian's own funds; plus any new equity proceeds
A36: Investment securities | B36: ='Standalone Summary'!$B$12 -> 6200 | C36: ='Standalone Summary'!$C$12 -> 900 | D36: 0 | E36: =B36+C36+D36 -> 7100
A37: Residential mortgages | B37: ='Standalone Summary'!$B$13 -> 19500 | C37: ='Standalone Summary'!$C$13 -> 0 | D37: 0 | E37: =B37+C37+D37 -> 19500
A38: Commercial & business loans | B38: ='Standalone Summary'!$B$14 -> 8400 | C38: ='Standalone Summary'!$C$14 -> 0 | D38: 0 | E38: =B38+C38+D38 -> 8400
A39: Credit card receivables (net) | B39: ='Standalone Summary'!$B$15 -> 1150 | C39: ='Standalone Summary'!$C$15 -> 7200 | D39: =-'Cover & Assumptions'!$B$64 -> -115 | E39: =B39+C39+D39 -> 8235 | F39: Day-1 IFRS 9 provisioning gross-up
A40: Other consumer loans | B40: ='Standalone Summary'!$B$16 -> 2950 | C40: ='Standalone Summary'!$C$16 -> 1150 | D40: 0 | E40: =B40+C40+D40 -> 4100
A41: Goodwill created on acquisition | B41: 0 | C41: 0 | D41: =B15 -> 865 | E41: =B41+C41+D41 -> 865 | F41: A straight CET1 deduction — see the capital walk below
A42: Other assets | B42: ='Standalone Summary'!$B$17 -> 1000 | C42: ='Standalone Summary'!$C$17 -> 500 | D42: 0 | E42: =B42+C42+D42 -> 1500
A43: Total assets | B43: =SUM(B35:B42) -> 41000 | C43: =SUM(C35:C42) -> 10400 | D43: =SUM(D35:D42) -> 1309.5 | E43: =SUM(E35:E42) -> 52709.5
A45: Total deposits | B45: ='Standalone Summary'!$B$20 -> 32500 | C45: ='Standalone Summary'!$C$20 -> 6100 | D45: 0 | E45: =B45+C45+D45 -> 38600
A46: Wholesale borrowings / securitization debt | B46: ='Standalone Summary'!$B$21 -> 4300 | C46: ='Standalone Summary'!$C$21 -> 2900 | D46: ='Cover & Assumptions'!$B$45 -> 1155 | E46: =B46+C46+D46 -> 8355 | F46: New senior acquisition debt raised
A47: Other liabilities | B47: ='Standalone Summary'!$B$22 -> 900 | C47: ='Standalone Summary'!$C$22 -> 500 | D47: 0 | E47: =B47+C47+D47 -> 1400
A48: Total liabilities | B48: =SUM(B45:B47) -> 37700 | C48: =SUM(C45:C47) -> 9500 | D48: =SUM(D45:D47) -> 1155 | E48: =SUM(E45:E47) -> 48355
...

Sheet Deal C Pro Forma
A1: DEAL C PRO FORMA — PROJECT HARBORVIEW
A2: Meridian Trust Bank acquires Harborview Community Bank — all-cash acquisition
A3: Purchase accounting, pro forma balance sheet, capital walk and three-year accretion / dilution ($mm unless noted)
A5: FICTIONAL / SIMULATED DATA — All entities, financial figures, and events in this document are entirely fictional, created for illustrative/educational simulation purposes. They do not represent any real institution, and nothing here is financial, investment, or M&A advice.
A9: A. PURCHASE PRICE, VALUATION AND GOODWILL
A10: Item | B10: Amount | F10: Derivation / note
A11: Purchase price (all cash) | B11: ='Cover & Assumptions'!$B$68 -> 1050 | F11: Case spec s.5
A12: Target common equity at close (book) | B12: ='Standalone Summary'!$D$24 -> 800 | F12: Harborview Community Bank FY2025 book equity
A13: Less: Day-1 IFRS 9 provisioning gross-up | B13: =-'Cover & Assumptions'!$B$90 -> -12 | F13: Acquisition-accounting allowance build beyond the allowance already carried
A14: Net identifiable assets acquired | B14: =B12+B13 -> 788
A15: GOODWILL CREATED | B15: =B11-B14 -> 262 | F15: Purchase price less (target book equity less the Day-1 provision build)
A17: Implied price / book (x) | B17: =B11/B12 -> 1.3125
A18: Implied price / FY2025 earnings (x) | B18: =B11/'Standalone Summary'!$D$42 -> 14.189189
A19: Premium to standalone implied value | B19: =B11/'Cover & Assumptions'!$B$69-1 -> 0.19318182 | F19: Standalone value per case spec
A20: FY2025 earnings yield on purchase price | B20: ='Standalone Summary'!$D$42/B11 -> 0.07047619 | F20: Compare against the after-tax cost of the acquisition debt below — the gap is what drives accretion
A21: After-tax cost of acquisition debt | B21: ='Cover & Assumptions'!$B$73*(1-'Cover & Assumptions'!$B$20) -> 0.03589
A22: Spread of earnings yield over after-tax debt cost | B22: =B20-B21 -> 0.03458619
A24: B. SOURCES AND USES OF FUNDS
A25: Item | B25: Amount | C25: % of total | F25: Note
A26: Source: new senior debt | B26: ='Cover & Assumptions'!$B$71 -> 525 | C26: =B26/B28 -> 0.5
A27: Source: Meridian cash / excess capital | B27: ='Cover & Assumptions'!$B$72 -> 525 | C27: =B27/B28 -> 0.5
A28: Total sources | B28: =B26+B27 -> 1050
A29: Use: cash consideration to target shareholders | B29: =B11 -> 1050
A30: Total uses | B30: =B29 -> 1050
A31: Memo: one-time integration cost, expensed in Year 1 (pretax) | B31: ='Cover & Assumptions'!$B$89 -> 95
A33: C. PRO FORMA COMBINED BALANCE SHEET AT CLOSE ($mm)
A34: Line item | B34: Bank A FY2025A | C34: Harborview Community Bank FY2025A | D34: Deal adjustments | E34: Pro forma combined | F34: Adjustment note
A35: Cash & equivalents | B35: ='Standalone Summary'!$B$11 -> 1800 | C35: ='Standalone Summary'!$D$11 -> 520 | D35: =-'Cover & Assumptions'!$B$72+B68 -> -337.5 | E35: =B35+C35+D35 -> 1982.5 | F35: Less the cash consideration funded from Meridian's own funds; plus any new equity proceeds
A36: Investment securities | B36: ='Standalone Summary'!$B$12 -> 6200 | C36: ='Standalone Summary'!$D$12 -> 1650 | D36: 0 | E36: =B36+C36+D36 -> 7850
A37: Residential mortgages | B37: ='Standalone Summary'!$B$13 -> 19500 | C37: ='Standalone Summary'!$D$13 -> 4900 | D37: 0 | E37: =B37+C37+D37 -> 24400
A38: Commercial & business loans | B38: ='Standalone Summary'!$B$14 -> 8400 | C38: ='Standalone Summary'!$D$14 -> 1450 | D38: 0 | E38: =B38+C38+D38 -> 9850
A39: Credit card receivables (net) | B39: ='Standalone Summary'!$B$15 -> 1150 | C39: ='Standalone Summary'!$D$15 -> 340 | D39: =-'Cover & Assumptions'!$B$90 -> -12 | E39: =B39+C39+D39 -> 1478 | F39: Day-1 IFRS 9 provisioning gross-up
A40: Other consumer loans | B40: ='Standalone Summary'!$B$16 -> 2950 | C40: ='Standalone Summary'!$D$16 -> 640 | D40: 0 | E40: =B40+C40+D40 -> 3590
A41: Goodwill created on acquisition | B41: 0 | C41: 0 | D41: =B15 -> 262 | E41: =B41+C41+D41 -> 262 | F41: A straight CET1 deduction — see the capital walk below
A42: Other assets | B42: ='Standalone Summary'!$B$17 -> 1000 | C42: ='Standalone Summary'!$D$17 -> 300 | D42: 0 | E42: =B42+C42+D42 -> 1300
A43: Total assets | B43: =SUM(B35:B42) -> 41000 | C43: =SUM(C35:C42) -> 9800 | D43: =SUM(D35:D42) -> -87.5 | E43: =SUM(E35:E42) -> 50712.5
A45: Total deposits | B45: ='Standalone Summary'!$B$20 -> 32500 | C45: ='Standalone Summary'!$D$20 -> 8200 | D45: 0 | E45: =B45+C45+D45 -> 40700
A46: Wholesale borrowings / securitization debt | B46: ='Standalone Summary'!$B$21 -> 4300 | C46: ='Standalone Summary'!$D$21 -> 550 | D46: ='Cover & Assumptions'!$B$71 -> 525 | E46: =B46+C46+D46 -> 5375 | F46: New senior acquisition debt raised
A47: Other liabilities | B47: ='Standalone Summary'!$B$22 -> 900 | C47: ='Standalone Summary'!$D$22 -> 250 | D47: 0 | E47: =B47+C47+D47 -> 1150
A48: Total liabilities | B48: =SUM(B45:B47) -> 37700 | C48: =SUM(C45:C47) -> 9000 | D48: =SUM(D45:D47) -> 525 | E48: =SUM(E45:E47) -> 47225
...

Sheet Side-by-Side
A1: SIDE-BY-SIDE COMPARISON — DEAL B versus DEAL C
A2: Every figure below is a live link to the Deal B and Deal C pro forma sheets
A3: CAD $ millions unless noted. 'Favours' marks which deal the metric argues for.
A5: FICTIONAL / SIMULATED DATA — All entities, financial figures, and events in this document are entirely fictional, created for illustrative/educational simulation purposes. They do not represent any real institution, and nothing here is financial, investment, or M&A advice.
A9: TRANSACTION TERMS
A10: Metric | B10: Deal B Northfield Card | C10: Deal C Harborview Comm. | D10: Favours | E10: Comment
A11: Purchase price ($mm) | B11: ='Deal B Pro Forma'!$B$11 -> 1650 | C11: ='Deal C Pro Forma'!$B$11 -> 1050
A12: Implied price / book (x) | B12: ='Deal B Pro Forma'!$B$17 -> 1.8333333 | C12: ='Deal C Pro Forma'!$B$17 -> 1.3125 | E12: Northfield is priced at a far higher multiple of book
A13: Implied price / FY2025 earnings (x) | B13: ='Deal B Pro Forma'!$B$18 -> 4.7340334 | C13: ='Deal C Pro Forma'!$B$18 -> 14.189189 | E13: But far cheaper on earnings — Northfield runs a 38.8% ROE
A14: Premium to standalone implied value | B14: ='Deal B Pro Forma'!$B$19 -> 0.25 | C14: ='Deal C Pro Forma'!$B$19 -> 0.19318182
A15: New senior acquisition debt ($mm) | B15: ='Deal B Pro Forma'!$B$26 -> 1155 | C15: ='Deal C Pro Forma'!$B$26 -> 525
A16: Meridian cash / excess capital deployed ($mm) | B16: ='Deal B Pro Forma'!$B$27 -> 495 | C16: ='Deal C Pro Forma'!$B$27 -> 525
A17: Day-1 IFRS 9 provisioning gross-up ($mm) | B17: ='Cover & Assumptions'!$B$64 -> 115 | C17: ='Cover & Assumptions'!$B$90 -> 12
A18: GOODWILL CREATED ($mm) | B18: ='Deal B Pro Forma'!$B$15 -> 865 | C18: ='Deal C Pro Forma'!$B$15 -> 262 | D18: Deal C | E18: Deducted from CET1 in full — this is the capital cost of the premium
A19: One-time integration cost ($mm pretax) | B19: ='Deal B Pro Forma'!$B$31 -> 180 | C19: ='Deal C Pro Forma'!$B$31 -> 95
A20: Earnings yield on purchase price less after-tax debt cost | B20: ='Deal B Pro Forma'!$B$22 -> 0.17238636 | C20: ='Deal C Pro Forma'!$B$22 -> 0.03458619 | D20: Deal B | E20: The arithmetic source of accretion in a debt-funded cash deal
A22: SCALE AND STRATEGIC IMPACT
A23: Metric | B23: Deal B | C23: Deal C | D23: Favours | E23: Comment
A24: Target total assets ($mm) | B24: ='Standalone Summary'!$C$18 -> 10400 | C24: ='Standalone Summary'!$D$18 -> 9800
A25: Target gross card receivables ($mm) | B25: ='Standalone Summary'!$C$56 -> 7550 | C25: ='Standalone Summary'!$D$56 -> 355 | D25: Deal B | E25: Meridian's own book is only 1,190
A26: Combined gross card receivables ($mm) | B26: ='Standalone Summary'!$B$56+'Standalone Summary'!$C$56 -> 8740 | C26: ='Standalone Summary'!$B$56+'Standalone Summary'!$D$56 -> 1545 | D26: Deal B
A27: Uplift to Meridian's card book (x) | B27: =B26/'Standalone Summary'!$B$56 -> 7.3445378 | C27: =C26/'Standalone Summary'!$B$56 -> 1.2983193 | D27: Deal B | E27: The core strategic test: does the deal actually scale card lending?
A28: Target active card accounts (000s) | B28: ='Standalone Summary'!$C$55 -> 2850 | C28: ='Standalone Summary'!$D$55 -> 145 | D28: Deal B
A29: Target annual card purchase volume ($mm) | B29: ='Standalone Summary'!$C$65 -> 15300 | C29: ='Standalone Summary'!$D$65 -> 1350 | D29: Deal B
A30: Target posted APR | B30: ='Standalone Summary'!$C$66 -> 0.2299 | C30: ='Standalone Summary'!$D$66 -> 0.1999 | D30: Deal B
A31: Target revolve rate | B31: ='Standalone Summary'!$C$61 -> 0.71 | C31: ='Standalone Summary'!$D$61 -> 0.35 | E31: High revolve means high yield AND high adverse selection — the same fact cuts both ways
A32: Target committed but undrawn card lines ($mm) | B32: ='Standalone Summary'!$C$64 -> 12350 | C32: ='Standalone Summary'!$D$64 -> 1425 | D32: Deal C | E32: Contingent exposure acquired — the drawdown option the borrower holds
A33: Target deposits acquired ($mm) | B33: ='Standalone Summary'!$C$20 -> 6100 | C33: ='Standalone Summary'!$D$20 -> 8200 | D33: Deal C | E33: Harborview's are branch-sourced chequing/savings; Northfield's are broker and direct-to-consumer
A35: CAPITAL IMPACT
A36: Metric | B36: Deal B | C36: Deal C | D36: Favours | E36: Comment
A37: Pro forma combined RWA ($mm) | B37: ='Deal B Pro Forma'!$B$60 -> 29450 | C37: ='Deal C Pro Forma'!$B$60 -> 27050
A38: PRO FORMA CET1 RATIO — before equity raise | B38: ='Deal B Pro Forma'!$B$61 -> 0.074193548 | C38: ='Deal C Pro Forma'!$B$61 -> 0.10306839 | D38: Deal C | E38: Meridian standalone is 13.50%; the internal target is 11.00%
A39: Change versus standalone CET1 (bps) | B39: ='Deal B Pro Forma'!$B$63 -> -607.62204 | C39: ='Deal C Pro Forma'!$B$63 -> -318.8736 | D39: Deal C
A40: Headroom over the 7.0% regulatory minimum, before raise (bps) | B40: ='Deal B Pro Forma'!$B$78 -> 41.935484 | C40: ='Deal C Pro Forma'!$B$78 -> 330.68392 | D40: Deal C
A41: MINIMUM EQUITY RAISE TO RESTORE THE 11.0% TARGET ($mm) | B41: ='Deal B Pro Forma'!$B$68 -> 1054.5 | C41: ='Deal C Pro Forma'!$B$68 -> 187.5 | D41: Deal C | E41: The decisive capital number in this decision
A42: Raise as % of Meridian market capitalisation | B42: ='Deal B Pro Forma'!$B$74 -> 0.19971591 | C42: ='Deal C Pro Forma'!$B$74 -> 0.035511364 | D42: Deal C | E42: Equity-issuance execution risk
A43: New shares issued (mm) | B43: ='Deal B Pro Forma'!$B$70 -> 23.965909 | C43: ='Deal C Pro Forma'!$B$70 -> 4.2613636 | D43: Deal C
A44: Ownership dilution to existing shareholders | B44: ='Deal B Pro Forma'!$B$73 -> 0.16646933 | C44: ='Deal C Pro Forma'!$B$73 -> 0.034293553 | D44: Deal C
A45: Pro forma CET1 ratio — after equity raise | B45: ='Deal B Pro Forma'!$B$77 -> 0.11 | C45: ='Deal C Pro Forma'!$B$77 -> 0.11
A46: Memo: pro forma CET1 ratio if goodwill were nil | B46: ='Deal B Pro Forma'!$B$79 -> 0.10356537 | C46: ='Deal C Pro Forma'!$B$79 -> 0.11275416 | E46: Shows how much of the hit is unavoidable RWA absorption rather than the price paid
...

Sheet Decision Scorecard
A1: DECISION SCORECARD — WEIGHTED EVALUATION
A2: Framework per case spec section 6. Scores run 1 (poor) to 5 (excellent).
A3: Every score is anchored to a computed figure reproduced in the evidence block below — nothing here is asserted without a number behind it.
A5: FICTIONAL / SIMULATED DATA — All entities, financial figures, and events in this document are entirely fictional, created for illustrative/educational simulation purposes. They do not represent any real institution, and nothing here is financial, investment, or M&A advice.
A9: A. EVIDENCE BASE — THE COMPUTED NUMBERS BEHIND EACH SCORE
A10: Evidence metric | B10: Deal B | C10: Deal C | G10: Source tab
A11: Uplift to combined card receivables (x) | B11: ='Side-by-Side'!$B$27 -> 7.3445378 | C11: ='Side-by-Side'!$C$27 -> 1.2983193 | G11: Side-by-Side
A12: Card accounts acquired (000s) | B12: ='Standalone Summary'!$C$55 -> 2850 | C12: ='Standalone Summary'!$D$55 -> 145 | G12: Standalone Summary
A13: Year-3 EPS accretion / (dilution) | B13: ='Deal B Pro Forma'!$D$113 -> 0.88984436 | C13: ='Deal C Pro Forma'!$D$113 -> 0.28560704 | G13: Deal pro forma tabs
A14: Year-3 ROIC on total capital committed | B14: ='Deal B Pro Forma'!$D$131 -> 0.22971342 | C14: ='Deal C Pro Forma'!$D$131 -> 0.14394029 | G14: Deal pro forma tabs
A15: Pro forma CET1 ratio before any raise | B15: ='Deal B Pro Forma'!$B$61 -> 0.074193548 | C15: ='Deal C Pro Forma'!$B$61 -> 0.10306839 | G15: Deal pro forma tabs
A16: Equity raise required ($mm) | B16: ='Deal B Pro Forma'!$B$68 -> 1054.5 | C16: ='Deal C Pro Forma'!$B$68 -> 187.5 | G16: Deal pro forma tabs
A17: Equity raise as % of market capitalisation | B17: ='Deal B Pro Forma'!$B$74 -> 0.19971591 | C17: ='Deal C Pro Forma'!$B$74 -> 0.035511364 | G17: Deal pro forma tabs
A18: Acquired book net charge-off rate | B18: ='Standalone Summary'!$C$69 -> 0.046 | C18: ='Standalone Summary'!$D$69 -> 0.012 | G18: Standalone Summary
A19: Three-year change in acquired book 90+ DPD (bps) | B19: =('Standalone Summary'!$C$68-'Standalone Summary'!$B$102)*10000 -> 90 | C19: =('Standalone Summary'!$D$68-'Standalone Summary'!$B$107)*10000 -> 0 | G19: Standalone Summary trend block
A20: Acquired book expected loss rate (PD x LGD) | B20: ='Standalone Summary'!$C$73*'Standalone Summary'!$C$74 -> 0.04644 | C20: ='Standalone Summary'!$D$73*'Standalone Summary'!$D$74 -> 0.01092 | G20: Standalone Summary
A21: Integration cost as % of purchase price | B21: ='Cover & Assumptions'!$B$63/'Cover & Assumptions'!$B$42 -> 0.10909091 | C21: ='Cover & Assumptions'!$B$89/'Cover & Assumptions'!$B$68 -> 0.09047619 | G21: Cover & Assumptions
A23: B. WEIGHTED SCORECARD
A24: Dimension | B24: Weight | C24: Bank B score | D24: Bank C score | E24: Bank B weighted | F24: Bank C weighted | G24: Basis for the score (evidence-linked)
A25: Strategic fit / scale impact on the card lending goal | B25: 0.2 | C25: 5 | D25: 2 | E25: =$B$25*C25 -> 1 | F25: =$B$25*D25 -> 0.4 | G25: Deal B multiplies the combined card book about 7.3x and adds 2.85mm accounts at a 22.99% APR — it delivers the board's mandate in a single step. Deal C lifts the book only about 1.3x; it brings a clean underwriting model and a low-cost deposit base, but it does not scale card lending.
A26: Financial accretion (EPS accretion / dilution by Year 3) | B26: 0.2 | C26: 5 | D26: 4 | E26: =$B$26*C26 -> 1 | F26: =$B$26*D26 -> 0.8 | G26: Both deals are accretive. Deal B is far more so, because a 38.8% ROE book bought at roughly 4.7x earnings and 70% debt-funded is arithmetically powerful. Deal C's accretion is solid but leans heavily on the 10bps blended funding synergy, which is the single largest diligence item on that side.
A27: Risk-adjusted return (deal IRR / NPV net of credit risk) | B27: 0.2 | C27: 3 | D27: 4 | E27: =$B$27*C27 -> 0.6 | F27: =$B$27*D27 -> 0.8 | G27: In the base case Deal B's ROIC on committed capital is well ahead. Under the section-7 recession stress the two converge to within a few tens of basis points (see Stress Test, section F) — Deal B's excess return is a credit-risk premium rather than durable alpha, and its variance is several times Deal C's.
A28: Capital impact (pro forma CET1, equity raise need) | B28: 0.15 | C28: 1 | D28: 4 | E28: =$B$28*C28 -> 0.15 | F28: =$B$28*D28 -> 0.6 | G28: Deal B takes pro forma CET1 to about 7.4% — some 358bps below the internal target and barely above the 7.0% regulatory floor — forcing a raise of roughly $1.05bn, about 20% of market capitalisation. Deal C dips about 69bps below target and can be self-cured out of retained earnings within roughly two quarters.
A29: Credit / asset quality risk (delinquency trend, PD/LGD, provisioning volatility) | B29: 0.15 | C29: 1 | D29: 5 | E29: =$B$29*C29 -> 0.15 | F29: =$B$29*D29 -> 0.75 | G29: Northfield: NCO 4.6% and rising, 90+ DPD 2.4% (up 90bps in three years), PD 5.4%, LGD 86%, Stage 3 6.5%, plus 12,350 of undrawn lines. Harborview: NCO 1.2% flat, 90+ DPD 0.5% flat, PD 1.4%, LGD 78%, Stage 3 1.0%.
A30: Regulatory / conduct and integration risk | B30: 0.1 | C30: 1 | D30: 5 | E30: =$B$30*C30 -> 0.1 | F30: =$B$30*D30 -> 0.5 | G30: Northfield carries an unretired 2024 CLI consent and affordability remediation, plus a $180mm integration bill (10.9% of price) covering both technology and compliance. Harborview is a clean branch and back-office overlap at $95mm (9.0% of price).
A31: WEIGHTED TOTAL | B31: =SUM(B25:B30) -> 1 | E31: =SUM(E25:E30) -> 3 | F31: =SUM(F25:F30) -> 3.85
A32: Cross-check via SUMPRODUCT | E32: =SUMPRODUCT($B$25:$B$30,C25:C30) -> 3 | F32: =SUMPRODUCT($B$25:$B$30,D25:D30) -> 3.85
A33: SCORECARD WINNER | E33: =IF(E31>F31,"DEAL B — NORTHFIELD",IF(F31>E31,"DEAL C — HARBORVIEW","TIE")) -> DEAL C — HARBORVIEW
A34: Weighted-score margin | E34: =ABS(E31-F31) -> 0.85
A36: C. IS THE CONCLUSION SENSITIVE TO A SINGLE JUDGEMENT CALL?
A37: Test | B37: Deal B | C37: Deal C | D37: Result | G37: Comment
A38: Weighted score on the two GROWTH dimensions only (strategic fit + accretion) | C38: =E25+E26 -> 2 | D38: =F25+F26 -> 1.2 | E38: =IF(C38>D38,"Deal B wins","Deal C wins") -> Deal B wins
A39: Weighted score on the four RISK dimensions only (risk-adj. return, capital, credit, conduct) | C39: =E27+E28+E29+E30 -> 1 | D39: =F27+F28+F29+F30 -> 2.65 | E39: =IF(C39>D39,"Deal B wins","Deal C wins") -> Deal C wins
A40: Break-even: the capital-impact score Deal B would need to draw level overall | C40: =C28+(F31-E31)/$B$28 -> 6.6666667 | G40: Compare against the maximum possible score of 5
A41: Break-even: the credit-risk score Deal B would need to draw level overall | C41: =C29+(F31-E31)/$B$29 -> 6.6666667 | G41: Compare against the maximum possible score of 5
A42: Even scoring Deal B a perfect 5 on capital impact — which the computed 7.4% pro forma CET1 flatly contradicts — would not overturn the result on these weights. The conclusion does not rest on any single judgement call.

Sheet Stress Test
A1: STRESS TEST — RECESSION SCENARIO (case spec section 7)
A2: Card NCO +200bps and 90+ DPD +150bps on the acquired portfolios; +50bps NCO on Meridian's existing prime book
A3: Stress year modelled: FY2026E, Year 1 post-close and the most binding point for pro forma capital. $mm unless noted.
A5: FICTIONAL / SIMULATED DATA — All entities, financial figures, and events in this document are entirely fictional, created for illustrative/educational simulation purposes. They do not represent any real institution, and nothing here is financial, investment, or M&A advice.
A9: A. STRESS PARAMETERS
A10: Parameter | B10: Value | E10: Source
A11: Net charge-off uplift — acquired card portfolios | B11: ='Cover & Assumptions'!$B$94 -> 0.02 | E11: Case spec s.7
A12: 90+ DPD uplift — acquired card portfolios | B12: ='Cover & Assumptions'!$B$95 -> 0.015 | E12: Case spec s.7
A13: Net charge-off uplift — Meridian's existing card book | B13: ='Cover & Assumptions'!$B$96 -> 0.005 | E13: Case spec s.7 — prime and transactor-heavy, so it flexes less
A14: EAD migration — share of undrawn lines drawn under stress | B14: ='Cover & Assumptions'!$B$97 -> 0.05 | E14: Model overlay: distressed borrowers draw before they default
A15: Mechanics. The charge-off uplift flows straight to provision expense. The 90+ DPD uplift moves balances into IFRS 9 Stage 3, where the allowance is a lifetime expected credit loss — modelled as the migrated balance multiplied by the book's own LGD. The EAD overlay converts undrawn commitments carried at a 10% CCF into on-balance-sheet exposure at a 75% risk weight.
A17: B. INCREMENTAL PROVISION EXPENSE UNDER STRESS (FY2026E)
A18: Component | B18: Deal B | C18: Deal C | E18: Calculation
A19: Acquired book gross card receivables — FY2026E | B19: ='Standalone Summary'!$C$137 -> 8305 | C19: ='Standalone Summary'!$C$150 -> 369.2
A20: Acquired book LGD | B20: ='Standalone Summary'!$C$74 -> 0.86 | C20: ='Standalone Summary'!$D$74 -> 0.78
A21: Incremental charge-offs on the acquired book | B21: =B19*'Cover & Assumptions'!$B$94 -> 166.1 | C21: =C19*'Cover & Assumptions'!$B$94 -> 7.384 | E21: gross receivables x +200bps
A22: Stage 3 migration — lifetime ECL build on the acquired book | B22: =B19*'Cover & Assumptions'!$B$95*B20 -> 107.1345 | C22: =C19*'Cover & Assumptions'!$B$95*C20 -> 4.31964 | E22: gross receivables x +150bps x LGD
A23: Meridian existing gross card receivables — FY2026E | B23: ='Standalone Summary'!$C$124 -> 1261.4 | C23: ='Standalone Summary'!$C$124 -> 1261.4
A24: Incremental charge-offs on Meridian's existing book | B24: =B23*'Cover & Assumptions'!$B$96 -> 6.307 | C24: =C23*'Cover & Assumptions'!$B$96 -> 6.307 | E24: gross receivables x +50bps
A25: TOTAL INCREMENTAL PROVISION EXPENSE (pretax) | B25: =B21+B22+B24 -> 279.5415 | C25: =C21+C22+C24 -> 18.01064
A26: After-tax impact on capital | B26: =B25*(1-'Cover & Assumptions'!$B$20) -> 206.86071 | C26: =C25*(1-'Cover & Assumptions'!$B$20) -> 13.327874
A27: Stress provision as a multiple of the deal's base-case Year-1 provision | B27: =B25/('Standalone Summary'!$C$120+'Standalone Summary'!$C$133) -> 0.51428847 | C27: =C25/('Standalone Summary'!$C$120+'Standalone Summary'!$C$146) -> 0.15612552
A29: C. EAD MIGRATION OVERLAY — RWA IMPACT
A30: Component | B30: Deal B | C30: Deal C | E30: Calculation
A31: Acquired book undrawn card lines — FY2026E | B31: ='Standalone Summary'!$C$138 -> 13585 | C31: ='Standalone Summary'!$C$151 -> 1482
A32: Undrawn balances drawn under stress | B32: =B31*'Cover & Assumptions'!$B$97 -> 679.25 | C32: =C31*'Cover & Assumptions'!$B$97 -> 74.1
A33: Incremental RWA (on balance sheet at 75% RW, less the 10% CCF already capitalised) | B33: =B32*('Cover & Assumptions'!$B$28-'Cover & Assumptions'!$B$27*'Cover & Assumptions'!$B$28) -> 458.49375 | C33: =C32*('Cover & Assumptions'!$B$28-'Cover & Assumptions'!$B$27*'Cover & Assumptions'!$B$28) -> 50.0175
A34: This is the option asymmetry at portfolio scale. The customer's drawdown right is exercised precisely when the bank would most like to cancel, and the regulatory 10% conversion factor capitalises only a tenth of the committed exposure until it converts. Buying Northfield means buying 12,350 of these options at once.
A36: D. STRESSED PRO FORMA CAPITAL
A37: Item | B37: Deal B | C37: Deal C | E37: Note
A38: Pro forma CET1 capital after the equity raise (base case) | B38: ='Deal B Pro Forma'!$B$76 -> 3239.5 | C38: ='Deal C Pro Forma'!$B$76 -> 2975.5
A39: Less: after-tax stress provision | B39: =-B26 -> -206.86071 | C39: =-C26 -> -13.327874
A40: Stressed CET1 capital | B40: =B38+B39 -> 3032.6393 | C40: =C38+C39 -> 2962.1721
A41: Pro forma RWA (base case) | B41: ='Deal B Pro Forma'!$B$60 -> 29450 | C41: ='Deal C Pro Forma'!$B$60 -> 27050
A42: Plus: EAD migration overlay | B42: =B33 -> 458.49375 | C42: =C33 -> 50.0175
A43: Stressed RWA | B43: =B41+B42 -> 29908.494 | C43: =C41+C42 -> 27100.018
A44: Base-case pro forma CET1 ratio, after the raise | B44: ='Deal B Pro Forma'!$B$77 -> 0.11 | C44: ='Deal C Pro Forma'!$B$77 -> 0.11
A45: STRESSED CET1 RATIO — with the equity raise | B45: =B40/B43 -> 0.10139726 | C45: =C40/C43 -> 0.10930517
A46: Stressed CET1 capital WITHOUT the equity raise | B46: ='Deal B Pro Forma'!$B$57-B26 -> 1978.1393 | C46: ='Deal C Pro Forma'!$B$57-C26 -> 2774.6721
A47: STRESSED CET1 RATIO — without the equity raise | B47: =B46/B43 -> 0.066139716 | C47: =C46/C43 -> 0.10238636
...
