Workbook

Sheet Cover & Summary
A1: HARBORVIEW COMMUNITY BANK
A2: Bank C — Target Option 2 (safety & funding). Small conservative community bank: strong low-cost deposit base, small high-quality low-yield card book, excellent capital ratios.
A3: Financial statement workbook | FY2023 – FY2025 | Currency: CAD $ millions unless noted | Fiscal year ended December 31 | Statutory tax rate 26%
A5: IMPORTANT — FICTIONAL DATA DISCLAIMER All entities, financial figures, and events in this document are entirely fictional, created for illustrative/educational simulation purposes. They do not represent any real institution, and nothing here is financial, investment, or M&A advice.
A9: HEADLINE METRICS ($ millions unless noted) | B9: FY2023 | C9: FY2024 | D9: FY2025 | E9: Notes / basis
A10: SCALE
A11: Total assets | B11: ='Balance Sheet'!B14 -> 9329 | C11: ='Balance Sheet'!C14 -> 9557 | D11: ='Balance Sheet'!D14 -> 9800 | E11: Link -> Balance Sheet
A12: Total loans & receivables, net | B12: ='Balance Sheet'!B12 -> 6960 | C12: ='Balance Sheet'!C12 -> 7144 | D12: ='Balance Sheet'!D12 -> 7330
A13: Total deposits | B13: ='Balance Sheet'!B19 -> 7820 | C13: ='Balance Sheet'!C19 -> 8005 | D13: ='Balance Sheet'!D19 -> 8200
A14: Common shareholders' equity | B14: ='Balance Sheet'!B23 -> 739 | C14: ='Balance Sheet'!C23 -> 767 | D14: ='Balance Sheet'!D23 -> 800
A15: EARNINGS
A16: Total revenue | B16: ='Income Statement'!B15 -> 287 | C16: ='Income Statement'!C15 -> 298 | D16: ='Income Statement'!D15 -> 309
A17: Provision for credit losses | B17: ='Income Statement'!B18 -> 12 | C17: ='Income Statement'!C18 -> 13 | D17: ='Income Statement'!D18 -> 14
A18: Net income | B18: ='Income Statement'!B23 -> 68 | C18: ='Income Statement'!C23 -> 71 | D18: ='Income Statement'!D23 -> 74 | E18: Link -> Income Statement
A19: Return on equity | B19: ='Key Ratios'!B23 -> 0.092016238 | C19: ='Key Ratios'!C23 -> 0.092568449 | D19: ='Key Ratios'!D23 -> 0.0925
A20: Return on assets | B20: ='Key Ratios'!B24 -> 0.0072890985 | C20: ='Key Ratios'!C24 -> 0.0074291096 | D20: ='Key Ratios'!D24 -> 0.0075510204
A21: Net interest margin | B21: ='Key Ratios'!B30 -> 0.027134503 | C21: ='Key Ratios'!C30 -> 0.027505136 | D21: ='Key Ratios'!D30 -> 0.027839644
A22: Efficiency ratio | B22: ='Key Ratios'!B33 -> 0.63763066 | C22: ='Key Ratios'!C33 -> 0.63422819 | D22: ='Key Ratios'!D33 -> 0.63106796
A23: CAPITAL
A24: CET1 capital | B24: ='Capital & Regulatory Ratios'!B6 -> 703 | C24: ='Capital & Regulatory Ratios'!C6 -> 729 | D24: ='Capital & Regulatory Ratios'!D6 -> 760
A25: Risk-weighted assets | B25: ='Capital & Regulatory Ratios'!B15 -> 4235 | C25: ='Capital & Regulatory Ratios'!C15 -> 4340 | D25: ='Capital & Regulatory Ratios'!D15 -> 4450
A26: CET1 ratio | B26: ='Capital & Regulatory Ratios'!B24 -> 0.16599764 | C26: ='Capital & Regulatory Ratios'!C24 -> 0.16797235 | D26: ='Capital & Regulatory Ratios'!D24 -> 0.17078652 | E26: Link -> Capital & Regulatory Ratios
A27: Tier 1 leverage ratio | B27: ='Capital & Regulatory Ratios'!B27 -> 0.080180084 | C27: ='Capital & Regulatory Ratios'!C27 -> 0.080987758 | D27: ='Capital & Regulatory Ratios'!D27 -> 0.082142857
A28: CREDIT CARD PORTFOLIO
A29: Active accounts (#) | B29: ='Credit Card Portfolio Detail'!B6 -> 137000 | C29: ='Credit Card Portfolio Detail'!C6 -> 141000 | D29: ='Credit Card Portfolio Detail'!D6 -> 145000
A30: Gross card receivables | B30: ='Credit Card Portfolio Detail'!B7 -> 328 | C30: ='Credit Card Portfolio Detail'!C7 -> 341 | D30: ='Credit Card Portfolio Detail'!D7 -> 355 | E30: Link -> Credit Card Portfolio Detail
A31: Annual purchase volume | B31: ='Credit Card Portfolio Detail'!B18 -> 1240 | C31: ='Credit Card Portfolio Detail'!C18 -> 1300 | D31: ='Credit Card Portfolio Detail'!D18 -> 1350
A32: Posted purchase APR | B32: ='Credit Card Portfolio Detail'!B23 -> 0.1999 | C32: ='Credit Card Portfolio Detail'!C23 -> 0.1999 | D32: ='Credit Card Portfolio Detail'!D23 -> 0.1999
A33: 90+ days past due | B33: ='Credit Card Portfolio Detail'!B27 -> 0.0055 | C33: ='Credit Card Portfolio Detail'!C27 -> 0.0052 | D33: ='Credit Card Portfolio Detail'!D27 -> 0.005
A34: Net charge-off rate | B34: ='Credit Card Portfolio Detail'!B29 -> 0.013 | C34: ='Credit Card Portfolio Detail'!C29 -> 0.0125 | D34: ='Credit Card Portfolio Detail'!D29 -> 0.012
A35: Allowance coverage (% of gross) | B35: ='Credit Card Portfolio Detail'!B10 -> 0.042682927 | C35: ='Credit Card Portfolio Detail'!C10 -> 0.041055718 | D35: ='Credit Card Portfolio Detail'!D10 -> 0.042253521
A37: WORKBOOK INTEGRITY CHECKS (all differences must be zero)
A38: Balance sheet: total assets less total liabilities & equity | B38: ='Balance Sheet'!B25 -> 0 | C38: ='Balance Sheet'!C25 -> 0 | D38: ='Balance Sheet'!D25 -> 0 | E38: =IF(AND(ABS(B38)<0.01,ABS(C38)<0.01,ABS(D38)<0.01),"BALANCED - OK","*** DOES NOT BALANCE ***") -> BALANCED - OK
A39: Income statement: revenue less PCL, opex and tax, less net income | B39: ='Income Statement'!B24 -> 0 | C39: ='Income Statement'!C24 -> 0 | D39: ='Income Statement'!D24 -> 0 | E39: =IF(AND(ABS(B39)<0.01,ABS(C39)<0.01,ABS(D39)<0.01),"TIES OUT - OK","*** DOES NOT TIE ***") -> TIES OUT - OK
A40: Equity roll-forward: opening + net income - distributions less closing equity | B40: ='Balance Sheet'!B32 -> 0 | C40: ='Balance Sheet'!C32 -> 0 | D40: ='Balance Sheet'!D32 -> 0 | E40: =IF(AND(ABS(B40)<0.01,ABS(C40)<0.01,ABS(D40)<0.01),"TIES - OK","*** CHECK ***") -> TIES - OK
A41: Card book: gross less allowance versus balance-sheet net card receivables | B41: ='Balance Sheet'!B37 -> 0 | C41: ='Balance Sheet'!C37 -> 0 | D41: ='Balance Sheet'!D37 -> 0 | E41: =IF(AND(ABS(B41)<0.01,ABS(C41)<0.01,ABS(D41)<0.01),"TIES - OK","*** CHECK ***") -> TIES - OK
A42: IFRS 9 staging: Stage 1 + Stage 2 + Stage 3 less 100% | B42: ='Credit Card Portfolio Detail'!B41 -> 0 | C42: ='Credit Card Portfolio Detail'!C41 -> 0 | D42: ='Credit Card Portfolio Detail'!D41 -> 0 | E42: =IF(AND(ABS(B42)<0.0001,ABS(C42)<0.0001,ABS(D42)<0.0001),"SUMS TO 100% - OK","*** CHECK ***") -> SUMS TO 100% - OK
A43: Card fee income on card tab versus income statement | B43: ='Credit Card Portfolio Detail'!B22-'Income Statement'!B11 -> 0 | C43: ='Credit Card Portfolio Detail'!C22-'Income Statement'!C11 -> 0 | D43: ='Credit Card Portfolio Detail'!D22-'Income Statement'!D11 -> 0 | E43: =IF(AND(ABS(B43)<0.01,ABS(C43)<0.01,ABS(D43)<0.01),"TIES - OK","*** CHECK ***") -> TIES - OK
A45: BASIS OF PREPARATION, CONVENTIONS & KEY ASSUMPTIONS
A46: 1. FY2025 is the case anchor year. Every FY2025 figure in this workbook is taken directly and unaltered from the M&A case-study spec (Sections 2–4). It is not re-derived.
...

Sheet Balance Sheet
A1: HARBORVIEW COMMUNITY BANK — CONSOLIDATED BALANCE SHEET
A2: As at December 31 | CAD $ millions | FY2025 = case anchor year (fixed); FY2023–FY2024 back-cast
A4: ($ millions unless noted) | B4: FY2023 | C4: FY2024 | D4: FY2025 | E4: Notes / basis
A5: ASSETS
A6: Cash & equivalents | B6: 495 | C6: 505 | D6: 520
A7: Investment securities | B7: 1590 | C7: 1618 | D7: 1650
A8: Residential mortgages | B8: 4675 | C8: 4790 | D8: 4900
A9: Commercial & business loans | B9: 1375 | C9: 1412 | D9: 1450
A10: Credit card receivables, net of allowance | B10: 314 | C10: 327 | D10: 340
A11: Other consumer loans | B11: 596 | C11: 615 | D11: 640
A12: Total loans & receivables, net | B12: =B8+B9+B10+B11 -> 6960 | C12: =C8+C9+C10+C11 -> 7144 | D12: =D8+D9+D10+D11 -> 7330 | E12: Sum of loan lines above
A13: Other assets | B13: 284 | C13: 290 | D13: 300
A14: TOTAL ASSETS | B14: =B6+B7+B8+B9+B10+B11+B13 -> 9329 | C14: =C6+C7+C8+C9+C10+C11+C13 -> 9557 | D14: =D6+D7+D8+D9+D10+D11+D13 -> 9800 | E14: Sum of all asset lines
A16: LIABILITIES & SHAREHOLDERS' EQUITY
A17: Deposits — chequing / savings | B17: 6000 | C17: 6150 | D17: 6300
A18: Deposits — term / GIC | B18: 1820 | C18: 1855 | D18: 1900
A19: Total deposits | B19: =B17+B18 -> 7820 | C19: =C17+C18 -> 8005 | D19: =D17+D18 -> 8200 | E19: Sum of deposit lines
A20: Wholesale borrowings | B20: 530 | C20: 540 | D20: 550
A21: Other liabilities | B21: 240 | C21: 245 | D21: 250
A22: Total liabilities | B22: =B19+B20+B21 -> 8590 | C22: =C19+C20+C21 -> 8790 | D22: =D19+D20+D21 -> 9000
A23: Common shareholders' equity | B23: 739 | C23: 767 | D23: 800
A24: TOTAL LIABILITIES & EQUITY | B24: =B22+B23 -> 9329 | C24: =C22+C23 -> 9557 | D24: =D22+D23 -> 9800
A25: Balance check (total assets less total liabilities & equity) | B25: =B14-B24 -> 0 | C25: =C14-C24 -> 0 | D25: =D14-D24 -> 0 | E25: =IF(AND(ABS(B25)<0.01,ABS(C25)<0.01,ABS(D25)<0.01),"BALANCED - OK","*** DOES NOT BALANCE ***") -> BALANCED - OK
A27: COMMON EQUITY ROLL-FORWARD
A28: Common equity, opening balance | B28: 715 | C28: =B23 -> 739 | D28: =C23 -> 767 | E28: FY2023 opening balance is a back-cast assumption; later years roll from prior year-end
A29: Net income for the year | B29: ='Income Statement'!B23 -> 68 | C29: ='Income Statement'!C23 -> 71 | D29: ='Income Statement'!D23 -> 74 | E29: Link -> Income Statement
A30: Less: dividends & share repurchases (derived) | B30: =-(B28+B29-B23) -> -44 | C30: =-(C28+C29-C23) -> -43 | D30: =-(D28+D29-D23) -> -41 | E30: Derived as the plug between opening equity + net income and closing equity
A31: Common equity, closing balance | B31: =B28+B29+B30 -> 739 | C31: =C28+C29+C30 -> 767 | D31: =D28+D29+D30 -> 800
A32: Equity roll-forward check (vs. reported common equity) | B32: =B31-B23 -> 0 | C32: =C31-C23 -> 0 | D32: =D31-D23 -> 0 | E32: =IF(AND(ABS(B32)<0.01,ABS(C32)<0.01,ABS(D32)<0.01),"TIES - OK","*** CHECK ***") -> TIES - OK
A34: MEMORANDUM ITEMS
A35: Gross credit card receivables | B35: ='Credit Card Portfolio Detail'!B7 -> 328 | C35: ='Credit Card Portfolio Detail'!C7 -> 341 | D35: ='Credit Card Portfolio Detail'!D7 -> 355 | E35: Link -> Credit Card Portfolio Detail
A36: Credit card allowance for credit losses | B36: ='Credit Card Portfolio Detail'!B8 -> 14 | C36: ='Credit Card Portfolio Detail'!C8 -> 14 | D36: ='Credit Card Portfolio Detail'!D8 -> 15 | E36: Link -> Credit Card Portfolio Detail
A37: Credit card receivables, net (check vs. balance sheet) | B37: =B35-B36-B10 -> 0 | C37: =C35-C36-C10 -> 0 | D37: =D35-D36-D10 -> 0 | E37: Should equal zero — gross less allowance ties to the balance-sheet card line
A38: Earning assets (investment securities + net loans) | B38: =B7+B8+B9+B10+B11 -> 8550 | C38: =C7+C8+C9+C10+C11 -> 8762 | D38: =D7+D8+D9+D10+D11 -> 8980 | E38: Denominator used for yield / NIM on the Key Ratios tab
A39: Interest-bearing liabilities (deposits + wholesale funding) | B39: =B19+B20 -> 8350 | C39: =C19+C20 -> 8545 | D39: =D19+D20 -> 8750 | E39: Denominator used for cost of funds on the Key Ratios tab
A40: Loan-to-deposit ratio | B40: =B12/B19 -> 0.89002558 | C40: =C12/C19 -> 0.89244222 | D40: =D12/D19 -> 0.89390244
A41: Common equity / total assets | B41: =B23/B14 -> 0.07921535 | C41: =C23/C14 -> 0.08025531 | D41: =D23/D14 -> 0.081632653
A43: Colour convention: blue = hardcoded input / case assumption | black = formula on this sheet | green = link to another tab.
A44: Back-cast basis (FY2023–FY2024): slow-and-safe profile per case spec — total assets CAGR ~2.5%/yr, card book ~4%/yr, credit quality stable/excellent throughout, CET1 stable and high (~16.5–17.1%) across all three years.
A45: Source for FY2025: M&A case-study spec, Section 2/3/4 (fictional). FY2025 anchor figures are fixed and unaltered.

Sheet Income Statement
A1: HARBORVIEW COMMUNITY BANK — CONSOLIDATED STATEMENT OF INCOME
A2: Year ended December 31 | CAD $ millions | FY2025 = case anchor year (fixed); FY2023–FY2024 back-cast
A4: ($ millions unless noted) | B4: FY2023 | C4: FY2024 | D4: FY2025 | E4: Notes / basis
A5: NET INTEREST INCOME
A6: Interest income | B6: 380 | C6: 398 | D6: 415
A7: Interest expense | B7: 148 | C7: 157 | D7: 165
A8: Net interest income | B8: =B6-B7 -> 232 | C8: =C6-C7 -> 241 | D8: =D6-D7 -> 250
A10: NON-INTEREST INCOME
A11: Interchange & credit card fee income | B11: ='Credit Card Portfolio Detail'!B22 -> 19 | C11: ='Credit Card Portfolio Detail'!C22 -> 20 | D11: ='Credit Card Portfolio Detail'!D22 -> 21 | E11: Link -> Card tab: purchase volume x 1.5% interchange + other card fees
A12: Other fee income | B12: 36 | C12: 37 | D12: 38
A13: Total non-interest income | B13: =B11+B12 -> 55 | C13: =C11+C12 -> 57 | D13: =D11+D12 -> 59
A15: TOTAL REVENUE | B15: =B8+B13 -> 287 | C15: =C8+C13 -> 298 | D15: =D8+D13 -> 309
A17: EXPENSES & PROVISIONS
A18: Provision for credit losses | B18: 12 | C18: 13 | D18: 14 | E18: IFRS 9 expected-credit-loss provision, all lending portfolios
A19: Non-interest expense (operating expense) | B19: 183 | C19: 189 | D19: 195
A20: Income before income taxes | B20: =B15-B18-B19 -> 92 | C20: =C15-C18-C19 -> 96 | D20: =D15-D18-D19 -> 100
A21: Statutory income tax rate | B21: 0.26 | C21: 0.26 | D21: 0.26 | E21: Case assumption: 26% throughout (spec Section 0)
A22: Income tax expense | B22: =ROUND(B20*B21,0) -> 24 | C22: =ROUND(C20*C21,0) -> 25 | D22: =ROUND(D20*D21,0) -> 26 | E22: Pre-tax income x statutory tax rate, rounded to the nearest $mm
A23: NET INCOME | B23: =B20-B22 -> 68 | C23: =C20-C22 -> 71 | D23: =D20-D22 -> 74
A24: Income statement tie-out (revenue less PCL, opex and tax, less net income) | B24: =B15-B18-B19-B22-B23 -> 0 | C24: =C15-C18-C19-C22-C23 -> 0 | D24: =D15-D18-D19-D22-D23 -> 0 | E24: =IF(AND(ABS(B24)<0.01,ABS(C24)<0.01,ABS(D24)<0.01),"TIES OUT - OK","*** DOES NOT TIE ***") -> TIES OUT - OK
A26: GROWTH & COMPOSITION
A27: Total revenue growth (YoY) | C27: =C15/B15-1 -> 0.038327526 | D27: =D15/C15-1 -> 0.036912752
A28: Net income growth (YoY) | C28: =C23/B23-1 -> 0.044117647 | D28: =D23/C23-1 -> 0.042253521
A29: Provision for credit losses growth (YoY) | C29: =C18/B18-1 -> 0.083333333 | D29: =D18/C18-1 -> 0.076923077
A30: Net interest income / total revenue | B30: =B8/B15 -> 0.80836237 | C30: =C8/C15 -> 0.80872483 | D30: =D8/D15 -> 0.80906149
A31: Non-interest income / total revenue | B31: =B13/B15 -> 0.19163763 | C31: =C13/C15 -> 0.19127517 | D31: =D13/D15 -> 0.19093851
A32: Provision for credit losses / total revenue | B32: =B18/B15 -> 0.041811847 | C32: =C18/C15 -> 0.043624161 | D32: =D18/D15 -> 0.045307443
A34: Colour convention: blue = hardcoded input / case assumption | black = formula on this sheet | green = link to another tab.
A35: Back-cast basis (FY2023–FY2024): slow-and-safe profile per case spec — total assets CAGR ~2.5%/yr, card book ~4%/yr, credit quality stable/excellent throughout, CET1 stable and high (~16.5–17.1%) across all three years.

Sheet Credit Card Portfolio Detail
A1: HARBORVIEW COMMUNITY BANK — CREDIT CARD PORTFOLIO DETAIL
A2: As at / for the year ended December 31 | CAD $ millions unless noted
A4: ($ millions unless noted) | B4: FY2023 | C4: FY2024 | D4: FY2025 | E4: Notes / basis
A5: PORTFOLIO SIZE & COMPOSITION
A6: Active accounts (#) | B6: 137000 | C6: 141000 | D6: 145000
A7: Gross credit card receivables | B7: 328 | C7: 341 | D7: 355
A8: Allowance for credit losses (IFRS 9 ECL) | B8: 14 | C8: 14 | D8: 15
A9: Net credit card receivables | B9: =B7-B8 -> 314 | C9: =C7-C8 -> 327 | D9: =D7-D8 -> 340 | E9: Ties to the balance-sheet credit card line
A10: Allowance coverage (% of gross receivables) | B10: =B8/B7 -> 0.042682927 | C10: =C8/C7 -> 0.041055718 | D10: =D8/D7 -> 0.042253521
A11: Average balance per active account ($, actual) | B11: =B7*1000000/B6 -> 2394.1606 | C11: =C7*1000000/C6 -> 2418.4397 | D11: =D7*1000000/D6 -> 2448.2759
A12: Revolve rate (% of balances carried / not paid in full) | B12: 0.345 | C12: 0.348 | D12: 0.35
A14: LINES, UTILISATION & PURCHASE VOLUME
A15: Total credit line exposure (approved limits) | B15: 1650 | C15: 1715 | D15: 1780
A16: Undrawn lines (unconditionally cancellable commitments) | B16: =B15-B7 -> 1322 | C16: =C15-C7 -> 1374 | D16: =D15-D7 -> 1425
A17: Utilisation (drawn / total lines, period-end) | B17: =B7/B15 -> 0.19878788 | C17: =C7/C15 -> 0.19883382 | D17: =D7/D15 -> 0.1994382
A18: Annual purchase volume | B18: 1240 | C18: 1300 | D18: 1350
A19: Interchange rate on purchase volume | B19: 0.015 | C19: 0.015 | D19: 0.015 | E19: Case assumption: 1.5% (spec Section 0)
A20: Interchange income | B20: =B18*B19 -> 18.6 | C20: =C18*C19 -> 19.5 | D20: =D18*D19 -> 20.25
A21: Other card fee income (annual / late / FX) | B21: 0.4 | C21: 0.5 | D21: 0.75
A22: Total interchange & card fee income | B22: =B20+B21 -> 19 | C22: =C20+C21 -> 20 | D22: =D20+D21 -> 21 | E22: Flows to the Income Statement non-interest income line
A23: Posted purchase APR | B23: 0.1999 | C23: 0.1999 | D23: 0.1999
A25: DELINQUENCY & LOSS PERFORMANCE
A26: 30+ days past due (% of gross receivables) | B26: 0.012 | C26: 0.0115 | D26: 0.011
A27: 90+ days past due (% of gross receivables) | B27: 0.0055 | C27: 0.0052 | D27: 0.005
A28: 90+ days past due ($) | B28: =B27*B7 -> 1.804 | C28: =C27*C7 -> 1.7732 | D28: =D27*D7 -> 1.775
A29: Net charge-off rate (% of average gross receivables) | B29: 0.013 | C29: 0.0125 | D29: 0.012
A30: Memo: gross receivables, prior year-end (FY2022 opening) | B30: 315 | C30: =B7 -> 328 | D30: =C7 -> 341 | E30: FY2022 opening balance is a back-cast assumption used only to average the FY2023 book
A31: Average gross receivables | B31: =(B7+B30)/2 -> 321.5 | C31: =(C7+C30)/2 -> 334.5 | D31: =(D7+D30)/2 -> 348
A32: Net charge-offs ($) | B32: =B29*B31 -> 4.1795 | C32: =C29*C31 -> 4.18125 | D32: =D29*D31 -> 4.176
A33: Reserve cushion: allowance coverage / net charge-off rate | B33: =B10/B29 -> 3.2833021 | C33: =C10/C29 -> 3.2844575 | D33: =D10/D29 -> 3.5211268 | E33: Years of the current loss run-rate covered by the standing allowance
A34: 90+ DPD / net charge-off rate | B34: =B27/B29 -> 0.42307692 | C34: =C27/C29 -> 0.416 | D34: =D27/D29 -> 0.41666667 | E34: Rising ratio signals losses still working through the delinquency pipeline
A36: IFRS 9 STAGING (% OF GROSS RECEIVABLES)
A37: Stage 1 — performing, 12-month ECL | B37: 0.946 | C37: 0.948 | D37: 0.95
A38: Stage 2 — significant increase in credit risk, lifetime ECL | B38: 0.043 | C38: 0.042 | D38: 0.04
A39: Stage 3 — credit-impaired (~90+ DPD), lifetime ECL | B39: 0.011 | C39: 0.01 | D39: 0.01
A40: Total | B40: =B37+B38+B39 -> 1 | C40: =C37+C38+C39 -> 1 | D40: =D37+D38+D39 -> 1
A41: Staging check (total less 100%) | B41: =B40-1 -> 0 | C41: =C40-1 -> 0 | D41: =D40-1 -> 0 | E41: =IF(AND(ABS(B41)<0.0001,ABS(C41)<0.0001,ABS(D41)<0.0001),"SUMS TO 100% - OK","*** CHECK ***") -> SUMS TO 100% - OK
A42: Stage 3 balances ($) | B42: =B39*B7 -> 3.608 | C42: =C39*C7 -> 3.41 | D42: =D39*D7 -> 3.55
A44: RISK PARAMETERS
A45: Blended 12-month probability of default (PD) | B45: 0.015 | C45: 0.0145 | D45: 0.014
...

Sheet Capital & Regulatory Ratios
A1: HARBORVIEW COMMUNITY BANK — CAPITAL & REGULATORY RATIOS
A2: As at December 31 | CAD $ millions | Basel III standardised approach (fictional Canadian jurisdiction)
A4: ($ millions unless noted) | B4: FY2023 | C4: FY2024 | D4: FY2025 | E4: Notes / basis
A5: REGULATORY CAPITAL
A6: Common Equity Tier 1 (CET1) capital | B6: 703 | C6: 729 | D6: 760
A7: Memo: common shareholders' equity (balance sheet) | B7: ='Balance Sheet'!B23 -> 739 | C7: ='Balance Sheet'!C23 -> 767 | D7: ='Balance Sheet'!D23 -> 800 | E7: Link -> Balance Sheet
A8: Memo: CET1 regulatory deductions (goodwill, intangibles, DTA) | B8: =B7-B6 -> 36 | C8: =C7-C6 -> 38 | D8: =D7-D6 -> 40
A9: Additional Tier 1 (AT1) instruments | B9: 45 | C9: 45 | D9: 45 | E9: Debt-classified AT1 sits within other liabilities / wholesale funding on the balance sheet
A10: Tier 1 capital | B10: =B6+B9 -> 748 | C10: =C6+C9 -> 774 | D10: =D6+D9 -> 805
A11: Tier 2 capital (eligible allowances & subordinated debt) | B11: 30 | C11: 32 | D11: 35
A12: Total regulatory capital | B12: =B10+B11 -> 778 | C12: =C10+C11 -> 806 | D12: =D10+D11 -> 840
A14: RISK-WEIGHTED ASSETS & EXPOSURE
A15: Risk-weighted assets (RWA) | B15: 4235 | C15: 4340 | D15: 4450
A16: Total assets | B16: ='Balance Sheet'!B14 -> 9329 | C16: ='Balance Sheet'!C14 -> 9557 | D16: ='Balance Sheet'!D14 -> 9800 | E16: Link -> Balance Sheet
A17: Undrawn credit card lines (unconditionally cancellable) | B17: ='Credit Card Portfolio Detail'!B16 -> 1322 | C17: ='Credit Card Portfolio Detail'!C16 -> 1374 | D17: ='Credit Card Portfolio Detail'!D16 -> 1425 | E17: Link -> Credit Card Portfolio Detail
A18: Credit conversion factor (CCF) on undrawn UCC card lines | B18: 0.1 | C18: 0.1 | D18: 0.1 | E18: Basel III finalisation: 10% CCF on unconditionally cancellable commitments (spec Section 0)
A19: Leverage / total exposure measure (assets + CCF x undrawn lines) | B19: =B16+B18*B17 -> 9461.2 | C19: =C16+C18*C17 -> 9694.4 | D19: =D16+D18*D17 -> 9942.5
A20: RWA density (RWA / total assets) | B20: =B15/B16 -> 0.45396077 | C20: =C15/C16 -> 0.4541174 | D20: =D15/D16 -> 0.45408163
A21: Implied blended risk weight (RWA / total exposure measure) | B21: =B15/B19 -> 0.44761764 | C21: =C15/C19 -> 0.44768114 | D21: =D15/D19 -> 0.44757355
A23: CAPITAL RATIOS
A24: CET1 ratio | B24: =B6/B15 -> 0.16599764 | C24: =C6/C15 -> 0.16797235 | D24: =D6/D15 -> 0.17078652
A25: Tier 1 capital ratio | B25: =B10/B15 -> 0.17662338 | C25: =C10/C15 -> 0.17834101 | D25: =D10/D15 -> 0.18089888
A26: Total capital ratio | B26: =B12/B15 -> 0.1837072 | C26: =C12/C15 -> 0.18571429 | D26: =D12/D15 -> 0.18876404
A27: Tier 1 leverage ratio (Tier 1 capital / total assets) | B27: =B10/B16 -> 0.080180084 | C27: =C10/C16 -> 0.080987758 | D27: =D10/D16 -> 0.082142857
A28: Basel III leverage ratio (Tier 1 / total exposure incl. CCF) | B28: =B10/B19 -> 0.079059739 | C28: =C10/C19 -> 0.079839908 | D28: =D10/D19 -> 0.080965552
A30: CAPITAL HEADROOM
A31: Regulatory minimum CET1 incl. capital conservation buffer | B31: 0.07 | C31: 0.07 | D31: 0.07 | E31: Illustrative: 4.5% Pillar 1 minimum + 2.5% capital conservation buffer
A32: CET1 surplus over regulatory minimum ($) | B32: =B6-B31*B15 -> 406.55 | C32: =C6-C31*C15 -> 425.2 | D32: =D6-D31*D15 -> 448.5
A33: CET1 headroom over regulatory minimum (bps) | B33: =(B24-B31)*10000 -> 959.97639 | C33: =(C24-C31)*10000 -> 979.7235 | D33: =(D24-D31)*10000 -> 1007.8652
A35: CET1 MOVEMENT
A36: CET1 capital growth (YoY) | C36: =C6/B6-1 -> 0.036984353 | D36: =D6/C6-1 -> 0.042524005
A37: RWA growth (YoY) | C37: =C15/B15-1 -> 0.024793388 | D37: =D15/C15-1 -> 0.025345622
A38: CET1 ratio change (bps, YoY) | C38: =(C24-B24)*10000 -> 19.747115 | D38: =(D24-C24)*10000 -> 28.141666
A40: RISK-WEIGHT & CCF ASSUMPTIONS APPLIED — CREDIT CARD EXPOSURES
A41: Risk weight — transactor exposures | B41: 0.45 | C41: 0.45 | D41: 0.45 | E41: Basel III finalisation standardised bucket (spec Section 0)
A42: Risk weight — revolver exposures | B42: 0.75 | C42: 0.75 | D42: 0.75 | E42: Basel III finalisation standardised bucket (spec Section 0)
A43: Revolve rate (share of balances revolving) | B43: ='Credit Card Portfolio Detail'!B12 -> 0.345 | C43: ='Credit Card Portfolio Detail'!C12 -> 0.348 | D43: ='Credit Card Portfolio Detail'!D12 -> 0.35 | E43: Link -> Credit Card Portfolio Detail
A44: Blended card risk weight (revolve x 75% + transactor x 45%) | B44: =B43*B42+(1-B43)*B41 -> 0.5535 | C44: =C43*C42+(1-C43)*C41 -> 0.5544 | D44: =D43*D42+(1-D43)*D41 -> 0.555
A45: Gross card receivables | B45: ='Credit Card Portfolio Detail'!B7 -> 328 | C45: ='Credit Card Portfolio Detail'!C7 -> 341 | D45: ='Credit Card Portfolio Detail'!D7 -> 355 | E45: Link -> Credit Card Portfolio Detail
A46: Card exposure at default (drawn + 10% CCF x undrawn) | B46: =B45+B18*B17 -> 460.2 | C46: =C45+C18*C17 -> 478.4 | D46: =D45+D18*D17 -> 497.5
...

Sheet Key Ratios
A1: HARBORVIEW COMMUNITY BANK — KEY RATIOS
A2: Three-year summary | All ratios computed by formula from the statement tabs — no ratio is hardcoded
A4: ($ millions unless noted) | B4: FY2023 | C4: FY2024 | D4: FY2025 | E4: Notes / basis
A5: INPUTS DRAWN FROM THE STATEMENT TABS
A6: Net income | B6: ='Income Statement'!B23 -> 68 | C6: ='Income Statement'!C23 -> 71 | D6: ='Income Statement'!D23 -> 74 | E6: Link -> Income Statement
A7: Total revenue | B7: ='Income Statement'!B15 -> 287 | C7: ='Income Statement'!C15 -> 298 | D7: ='Income Statement'!D15 -> 309 | E7: Link -> Income Statement
A8: Net interest income | B8: ='Income Statement'!B8 -> 232 | C8: ='Income Statement'!C8 -> 241 | D8: ='Income Statement'!D8 -> 250 | E8: Link -> Income Statement
A9: Total non-interest income | B9: ='Income Statement'!B13 -> 55 | C9: ='Income Statement'!C13 -> 57 | D9: ='Income Statement'!D13 -> 59 | E9: Link -> Income Statement
A10: Interest income | B10: ='Income Statement'!B6 -> 380 | C10: ='Income Statement'!C6 -> 398 | D10: ='Income Statement'!D6 -> 415 | E10: Link -> Income Statement
A11: Interest expense | B11: ='Income Statement'!B7 -> 148 | C11: ='Income Statement'!C7 -> 157 | D11: ='Income Statement'!D7 -> 165 | E11: Link -> Income Statement
A12: Non-interest expense | B12: ='Income Statement'!B19 -> 183 | C12: ='Income Statement'!C19 -> 189 | D12: ='Income Statement'!D19 -> 195 | E12: Link -> Income Statement
A13: Provision for credit losses | B13: ='Income Statement'!B18 -> 12 | C13: ='Income Statement'!C18 -> 13 | D13: ='Income Statement'!D18 -> 14 | E13: Link -> Income Statement
A14: Total assets | B14: ='Balance Sheet'!B14 -> 9329 | C14: ='Balance Sheet'!C14 -> 9557 | D14: ='Balance Sheet'!D14 -> 9800 | E14: Link -> Balance Sheet
A15: Common shareholders' equity | B15: ='Balance Sheet'!B23 -> 739 | C15: ='Balance Sheet'!C23 -> 767 | D15: ='Balance Sheet'!D23 -> 800 | E15: Link -> Balance Sheet
A16: Total loans & receivables, net | B16: ='Balance Sheet'!B12 -> 6960 | C16: ='Balance Sheet'!C12 -> 7144 | D16: ='Balance Sheet'!D12 -> 7330 | E16: Link -> Balance Sheet
A17: Earning assets | B17: ='Balance Sheet'!B38 -> 8550 | C17: ='Balance Sheet'!C38 -> 8762 | D17: ='Balance Sheet'!D38 -> 8980 | E17: Link -> Balance Sheet
A18: Interest-bearing liabilities | B18: ='Balance Sheet'!B39 -> 8350 | C18: ='Balance Sheet'!C39 -> 8545 | D18: ='Balance Sheet'!D39 -> 8750 | E18: Link -> Balance Sheet
A19: Total deposits | B19: ='Balance Sheet'!B19 -> 7820 | C19: ='Balance Sheet'!C19 -> 8005 | D19: ='Balance Sheet'!D19 -> 8200 | E19: Link -> Balance Sheet
A20: Risk-weighted assets | B20: ='Capital & Regulatory Ratios'!B15 -> 4235 | C20: ='Capital & Regulatory Ratios'!C15 -> 4340 | D20: ='Capital & Regulatory Ratios'!D15 -> 4450 | E20: Link -> Capital & Regulatory Ratios
A22: PROFITABILITY
A23: Return on equity (ROE) | B23: =B6/B15 -> 0.092016238 | C23: =C6/C15 -> 0.092568449 | D23: =D6/D15 -> 0.0925 | E23: Net income / period-end common equity
A24: Return on assets (ROA) | B24: =B6/B14 -> 0.0072890985 | C24: =C6/C14 -> 0.0074291096 | D24: =D6/D14 -> 0.0075510204 | E24: Net income / period-end total assets
A25: Return on risk-weighted assets | B25: =B6/B20 -> 0.016056671 | C25: =C6/C20 -> 0.016359447 | D25: =D6/D20 -> 0.016629213
A27: MARGIN & FUNDING
A28: Yield on earning assets | B28: =B10/B17 -> 0.044444444 | C28: =C10/C17 -> 0.045423419 | D28: =D10/D17 -> 0.046213808
A29: Cost of funds (interest expense / interest-bearing liabilities) | B29: =B11/B18 -> 0.017724551 | C29: =C11/C18 -> 0.018373318 | D29: =D11/D18 -> 0.018857143
A30: Net interest margin (NII / earning assets) | B30: =B8/B17 -> 0.027134503 | C30: =C8/C17 -> 0.027505136 | D30: =D8/D17 -> 0.027839644
A32: EFFICIENCY
A33: Efficiency ratio (non-interest expense / total revenue) | B33: =B12/B7 -> 0.63763066 | C33: =C12/C7 -> 0.63422819 | D33: =D12/D7 -> 0.63106796
A34: Non-interest income / total revenue | B34: =B9/B7 -> 0.19163763 | C34: =C9/C7 -> 0.19127517 | D34: =D9/D7 -> 0.19093851
A35: Non-interest expense / total assets | B35: =B12/B14 -> 0.01961625 | C35: =C12/C14 -> 0.01977608 | D35: =D12/D14 -> 0.019897959
A37: CREDIT QUALITY
A38: Provision for credit losses / net loans | B38: =B13/B16 -> 0.0017241379 | C38: =C13/C16 -> 0.0018197088 | D38: =D13/D16 -> 0.0019099591
A39: Credit card net charge-off rate | B39: ='Credit Card Portfolio Detail'!B29 -> 0.013 | C39: ='Credit Card Portfolio Detail'!C29 -> 0.0125 | D39: ='Credit Card Portfolio Detail'!D29 -> 0.012 | E39: Link -> Credit Card Portfolio Detail
A40: Credit card 90+ days past due | B40: ='Credit Card Portfolio Detail'!B27 -> 0.0055 | C40: ='Credit Card Portfolio Detail'!C27 -> 0.0052 | D40: ='Credit Card Portfolio Detail'!D27 -> 0.005 | E40: Link -> Credit Card Portfolio Detail
A41: Credit card allowance coverage | B41: ='Credit Card Portfolio Detail'!B10 -> 0.042682927 | C41: ='Credit Card Portfolio Detail'!C10 -> 0.041055718 | D41: ='Credit Card Portfolio Detail'!D10 -> 0.042253521 | E41: Link -> Credit Card Portfolio Detail
A43: BALANCE SHEET & CAPITAL STRENGTH
A44: Loan-to-deposit ratio | B44: =B16/B19 -> 0.89002558 | C44: =C16/C19 -> 0.89244222 | D44: =D16/D19 -> 0.89390244
A45: Common equity / total assets | B45: =B15/B14 -> 0.07921535 | C45: =C15/C14 -> 0.08025531 | D45: =D15/D14 -> 0.081632653
A46: CET1 ratio | B46: ='Capital & Regulatory Ratios'!B24 -> 0.16599764 | C46: ='Capital & Regulatory Ratios'!C24 -> 0.16797235 | D46: ='Capital & Regulatory Ratios'!D24 -> 0.17078652 | E46: Link -> Capital & Regulatory Ratios
...
